<?xml version="1.0"?>
<robot xmlns:xacro="http://www.ros.org/wiki/xacro" name="chimera" >
  <xacro:property name="width" value=".2" />

  <!-- Copied from https://github.com/elephantrobotics/mycobot_ros/pull/47/files#diff-376dbc4a3acb2831ff5adea9612541636ce126703a5f9477713e5dd388a4e196. Can be found here: https://en.wikipedia.org/wiki/List_of_moments_of_inertia#List_of_3D_inertia_tensors as well.-->
  <xacro:macro name="box_inertial" params="m w d h">
    <inertial>
      <mass value="${m}" />
      <inertia ixx="${m*(h*h + d*d)/12}" ixy = "0" ixz = "0"
      iyy="${m*(h*h+w*w)/12}" iyz = "0"
      izz="${m*(w*w+d*d)/12}" />
    </inertial>
  </xacro:macro>

  <xacro:macro name="hcylinder_inertial" params="m r h">
    <inertial>
      <mass value="${m}" />
      <inertia ixx="${m*(3*(r*r)+h*h)/12}" ixy = "0" ixz = "0"
      iyy="${m*(3*(r*r)+h*h)/12}" iyz = "0"
      izz="${m*(r*r)/12}" />
    </inertial>
  </xacro:macro>

  <!-- The joints are modelled as a cylinder, that encompasses the whole joint. -->
  <link name="base_footprint"/>
  <link name="base_link">
    <visual>
      <geometry>
	<mesh filename="package://chimera_description/meshes/base_link.stl"/>
      </geometry>
      <origin xyz = "0.0 0.0 0.0 " rpy = "0 0 0"/>
      <material name="">
	<color rgba="0 0.7 0 1"/>
      </material>
    </visual>
    <collision>
      <geometry>
	<mesh filename="package://chimera_description/meshes/base_link_collision.stl"/>
      </geometry>
    </collision>
    <xacro:box_inertial m="5.5" w="0.24" d="0.34" h="0.15"/>
  </link>

  <link name="joint1">
    <visual>
      <geometry>
       <mesh filename="package://chimera_description/meshes/joint1.dae"/>
      </geometry>
      <origin xyz = "0.0 0 0 " rpy = " 0 0 3.14159"/>
    </visual>
    <collision>
      <geometry>
       <mesh filename="package://chimera_description/meshes/joint1.dae"/>
        </geometry>
        <origin xyz = "0.0 0 0 " rpy = " 0 0 3.14159"/>
    </collision>
    <xacro:box_inertial m="0.25" w="0.1" d="0.1" h="0.1"/>
  </link>

  <link name="joint2">
    <visual>
      <geometry>
       <mesh filename="package://chimera_description/meshes/joint2.dae"/>
      </geometry>
      <origin xyz = "0.0 0 -0.06096 " rpy = " 0 0 -1.5708"/>
    </visual>
    <collision>
     <geometry>
       <mesh filename="package://chimera_description/meshes/joint2.dae"/>
      </geometry>
      <origin xyz = "0.0 0 -0.06096 " rpy = " 0 0 -1.5708"/>
    </collision>
    <xacro:hcylinder_inertial m="0.1" r="0.025" h="0.087"/>
  </link>

  <link name="joint3">
    <visual>
      <geometry>
       <mesh filename="package://chimera_description/meshes/joint3.dae"/>
      </geometry>
    <origin xyz = "0.0 0 0.03256 " rpy = " 0 -1.5708 0"/>
    </visual>
    <collision>
      <geometry>
       <mesh filename="package://chimera_description/meshes/joint3.dae"/>
      </geometry>
      <origin xyz = "0.0 0 0.03256 " rpy = " 0 -1.5708 0"/>
    </collision>
    <xacro:hcylinder_inertial m="0.2" r="0.03" h="0.155"/>
  </link>

  <link name="joint4">
    <visual>
      <geometry>
       <mesh filename="package://chimera_description/meshes/joint4.dae"/>
      </geometry>
      <origin xyz = "0.0 0 0.03056 " rpy = " 0 -1.5708 0"/>
    </visual>
    <collision>
      <geometry>
       <mesh filename="package://chimera_description/meshes/joint4.dae"/>
      </geometry>
      <origin xyz = "0.0 0 0.03056 " rpy = " 0 -1.5708 0"/>
    </collision>
    <xacro:hcylinder_inertial m="0.18" r="0.0275" h="0.136"/>
  </link>

  <link name="joint5">
    <visual>
      <geometry>
       <mesh filename="package://chimera_description/meshes/joint5.dae"/>
      </geometry>
    <origin xyz = "0.0 0 -0.03356 " rpy = " -1.5708 0 0"/>
    </visual>
    <collision>
       <geometry>
       <mesh filename="package://chimera_description/meshes/joint5.dae"/>
      </geometry>
      <origin xyz = "0.0 0 -0.03356 " rpy = " -1.5708 0 0"/>
    </collision>
    <xacro:hcylinder_inertial m="0.1" r="0.0275" h="0.06"/>
  </link>

  <link name="joint6">
    <visual>
      <geometry>
       <mesh filename="package://chimera_description/meshes/joint6.dae"/>
      </geometry>
    <origin xyz = "0 0.00 -0.038 " rpy = " 0 0 0"/>
    </visual>
    <collision>
      <geometry>
       <mesh filename="package://chimera_description/meshes/joint6.dae"/>
      </geometry>
    <origin xyz = "0 0.00 -0.038 " rpy = " 0 0 0"/>
    </collision>
    <xacro:hcylinder_inertial m="0.1" r="0.018" h="0.06"/>
  </link>

  <link name="joint6_flange">
    <visual>
      <geometry>
       <mesh filename="package://chimera_description/meshes/joint7.dae"/>
      </geometry>
    <origin xyz = "0.0 0 -0.012 " rpy = " 0 0 0"/>
    </visual>
    <collision>
      <geometry>
       <mesh filename="package://chimera_description/meshes/joint7.dae"/>
      </geometry>
    <origin xyz = "0.0 0 -0.012 " rpy = " 0 0 0"/>
    </collision>
    <xacro:hcylinder_inertial m="0.05" r="0.018" h="0.02"/>
  </link>

  <joint name="base_joint" type="fixed">
    <parent link="base_footprint"/>
    <child link="base_link"/>
    <origin xyz="0.0 0.0 0.08" rpy="0 0 0"/>
  </joint>

  <joint name="base_link_to_arm" type="fixed">
    <parent link="base_link"/>
    <child link="joint1"/>
    <origin xyz="-0.03 0.0 0.087" rpy="0 0 0"/>
  </joint>

  <joint name="joint2_to_joint1" type="revolute">
    <axis xyz="0 0 1"/>
    <limit effort = "1000.0" lower = "-3.14" upper = "3.14159" velocity = "0"/>
    <parent link="joint1"/>
    <child link="joint2"/>
    <origin xyz= "0 0 0.13156" rpy = "0 0 1.5708"/>  
  </joint>

  <joint name="joint3_to_joint2" type="revolute">
    <axis xyz="0 0 1"/>
    <limit effort = "1000.0" lower = "-3.14" upper = "3.14159" velocity = "0"/>
    <parent link="joint2"/>
    <child link="joint3"/>
    <origin xyz= "0 0  0" rpy = "0 1.5708 -1.5708"/>  
  </joint>

  <joint name="joint4_to_joint3" type="revolute">
    <axis xyz=" 0 0 1"/>
    <limit effort = "1000.0" lower = "-3.14" upper = "3.14159" velocity = "0"/>
    <parent link="joint3"/>
    <child link="joint4"/>
    <origin xyz= "  -0.1104 0 0   " rpy = "0 0 0"/>  
  </joint>

  <joint name="joint5_to_joint4" type="revolute">
    <axis xyz=" 0 0 1"/>
    <limit effort = "1000.0" lower = "-3.14" upper = "3.14159" velocity = "0"/>
    <parent link="joint4"/>
    <child link="joint5"/>
    <origin xyz= "-0.096 0 0.06462" rpy = "0 0 -1.5708"/>  
  </joint>

  <joint name="joint6_to_joint5" type="revolute">
    <axis xyz="0 0 1"/>
    <limit effort = "1000.0" lower = "-3.14" upper = "3.14159" velocity = "0"/>
    <parent link="joint5"/>
    <child link="joint6"/>
    <origin xyz= "0 -0.07318 0" rpy = "1.5708 -1.5708 0"/>  
  </joint>
  
  <joint name="joint6output_to_joint6" type="revolute">
    <axis xyz="0 0 1"/>
    <limit effort = "1000.0" lower = "-3.14" upper = "3.14159" velocity = "0"/>
    <parent link="joint6"/>
    <child link="joint6_flange"/>
    <origin xyz= "0 0.0456 0" rpy = "-1.5708 0 0"/>  
  </joint>

</robot>
