<?xml version="1.0"?>
<robot  xmlns:xacro="http://www.ros.org/wiki/xacro" name="chimera" >
  <xacro:property name="width" value=".2" />
  
  <link name="base_footprint"/>
  <link name="base_link">
    <visual>
      <geometry>
	<mesh filename="package://chimera_description/meshes/base_link.stl"/>
      </geometry>
      <origin xyz = "0.0 0 0 " rpy = "0 0 0"/>
      <material name="">
	<color rgba="0 0.7 0 1"/>
      </material>
    </visual>
    <collision>
      <geometry>
	<mesh filename="package://chimera_description/meshes/base_link_collision.stl"/>
      </geometry>
    </collision>
  </link>

  
  <link name="joint1">
    <visual>
      <geometry>
	     <!--- 0.0 0 -0.04  1.5708 3.14159-->
       <mesh filename="package://chimera_description/meshes/joint1.dae"/>
      </geometry>
      <origin xyz = "0.0 0 0 " rpy = " 0 0 3.14159"/>
    </visual>
    <collision>
      <geometry>
	     <!--- 0.0 0 -0.04  1.5708 3.14159-->
       <mesh filename="package://chimera_description/meshes/joint1.dae"/>
        </geometry>
        <origin xyz = "0.0 0 0 " rpy = " 0 0 3.14159"/>
    </collision>
  </link>

  
  <link name="joint2">
    <visual>
      <geometry>
       <mesh filename="package://chimera_description/meshes/joint2.dae"/>
      </geometry>
      <origin xyz = "0.0 0 -0.06096 " rpy = " 0 0 -1.5708"/>
    </visual>
    <collision>
     <geometry>
       <mesh filename="package://chimera_description/meshes/joint2.dae"/>
      </geometry>
      <origin xyz = "0.0 0 -0.06096 " rpy = " 0 0 -1.5708"/>
    </collision>
  </link>


  <link name="joint3">
    <visual>
      <geometry>
       <mesh filename="package://chimera_description/meshes/joint3.dae"/>
      </geometry>
    <origin xyz = "0.0 0 0.03256 " rpy = " 0 -1.5708 0"/>
    </visual>
    <collision>
      <geometry>
       <mesh filename="package://chimera_description/meshes/joint3.dae"/>
      </geometry>
      <origin xyz = "0.0 0 0.03256 " rpy = " 0 -1.5708 0"/>
    </collision>
  </link>


  <link name="joint4">
    <visual>
      <geometry>
       <!--- 0.0 0 -0.04 -->
       <mesh filename="package://chimera_description/meshes/joint4.dae"/>
      </geometry>
      <origin xyz = "0.0 0 0.03056 " rpy = " 0 -1.5708 0"/>
    </visual>
    <collision>
      <geometry>
       <!--- 0.0 0 -0.04 -->
       <mesh filename="package://chimera_description/meshes/joint4.dae"/>
      </geometry>
      <origin xyz = "0.0 0 0.03056 " rpy = " 0 -1.5708 0"/>
    </collision>
  </link>


  <link name="joint5">
    <visual>
      <geometry>
       <!--- 0.0 0 -0.04 -->
       <mesh filename="package://chimera_description/meshes/joint5.dae"/>
      </geometry>
    <origin xyz = "0.0 0 -0.03356 " rpy = " -1.5708 0 0"/>
    </visual>
    <collision>
       <geometry>
       <!--- 0.0 0 -0.04 -->
       <mesh filename="package://chimera_description/meshes/joint5.dae"/>
      </geometry>
      <origin xyz = "0.0 0 -0.03356 " rpy = " -1.5708 0 0"/>
    </collision>
  </link>


  <link name="joint6">
    <visual>
      <geometry>
       <!--- 0.0 0 -0.04 -->
       <mesh filename="package://chimera_description/meshes/joint6.dae"/>
      </geometry>
    <origin xyz = "0 0.00 -0.038 " rpy = " 0 0 0"/>
    </visual>
    <collision>
      <geometry>
       <!--- 0.0 0 -0.04 -->
       <mesh filename="package://chimera_description/meshes/joint6.dae"/>
      </geometry>
    <origin xyz = "0 0.00 -0.038 " rpy = " 0 0 0"/>
    </collision>
  </link>


  <link name="joint6_flange">
    <visual>
      <geometry>
       <!--- 0.0 0 -0.04 -->
       <mesh filename="package://chimera_description/meshes/joint7.dae"/>
      </geometry>
    <origin xyz = "0.0 0 -0.012 " rpy = " 0 0 0"/>
    </visual>
    <collision>
      <geometry>
       <!--- 0.0 0 -0.04 -->
       <mesh filename="package://chimera_description/meshes/joint7.dae"/>
      </geometry>
    <origin xyz = "0.0 0 -0.012 " rpy = " 0 0 0"/>
    </collision>
  </link>


  <joint name="joint2_to_joint1" type="revolute">
    <axis xyz="0 0 1"/>
    <limit effort = "1000.0" lower = "-3.14" upper = "3.14159" velocity = "0"/>
    <parent link="joint1"/>
    <child link="joint2"/>
    <origin xyz= "0 0 0.13156" rpy = "0 0 1.5708"/>  
  </joint>


  <joint name="joint3_to_joint2" type="revolute">
    <axis xyz="0 0 1"/>
    <limit effort = "1000.0" lower = "-3.14" upper = "3.14159" velocity = "0"/>
    <parent link="joint2"/>
    <child link="joint3"/>
    <origin xyz= "0 0  0" rpy = "0 1.5708 -1.5708"/>  
  </joint>


  <joint name="joint4_to_joint3" type="revolute">
    <axis xyz=" 0 0 1"/>
    <limit effort = "1000.0" lower = "-3.14" upper = "3.14159" velocity = "0"/>
    <parent link="joint3"/>
    <child link="joint4"/>
    <origin xyz= "  -0.1104 0 0   " rpy = "0 0 0"/>  
  </joint>

  <!-- wheels -->
  <link name="left_front_wheel">
    <visual>
      <origin rpy="1.57075 0 0" xyz="0 0 0"/>
      <geometry>
        <cylinder length="0.05" radius="0.05"/>
      </geometry>
      <material name="black"/>
    </visual>
  </link>

  <link name="left_mid_wheel">
    <visual>
      <origin rpy="1.57075 0 0" xyz="0 0 0"/>
      <geometry>
        <cylinder length="0.05" radius="0.05"/>
      </geometry>
      <material name="black"/>
    </visual>
  </link>
  
  <link name="left_back_wheel">
    <visual>
      <origin rpy="1.57075 0 0" xyz="0 0 0"/>
      <geometry>
        <cylinder length="0.05" radius="0.05"/>
      </geometry>
      <material name="black"/>
    </visual>
  </link>

  <joint name="left_front_wheel_joint" type="continuous">
    <axis rpy="0 0 0" xyz="0 1 0"/>
    <parent link="base_link"/>
    <child link="left_front_wheel"/>
    <origin rpy="0 0 0" xyz="0.12 0.09 -0.03"/>
  </joint>

  <joint name="left_mid_wheel_joint" type="continuous">
    <axis rpy="0 0 0" xyz="0 1 0"/>
    <parent link="base_link"/>
    <child link="left_mid_wheel"/>
    <origin rpy="0 0 0" xyz="0.0 0.09 -0.03"/>
  </joint>
  
  <joint name="left_back_wheel_joint" type="continuous">
    <axis rpy="0 0 0" xyz="0 1 0"/>
    <parent link="base_link"/>
    <child link="left_back_wheel"/>
    <origin rpy="0 0 0" xyz="-0.12 0.09 -0.03"/>
  </joint>
  
  <link name="right_front_wheel">
    <visual>
      <origin rpy="1.57075 0 0" xyz="0 0 0"/>
      <geometry>
        <cylinder length="0.05" radius="0.05"/>
      </geometry>
      <material name="black"/>
    </visual>
  </link>

  <link name="right_mid_wheel">
    <visual>
      <origin rpy="1.57075 0 0" xyz="0 0 0"/>
      <geometry>
        <cylinder length="0.05" radius="0.05"/>
      </geometry>
      <material name="black"/>
    </visual>
  </link>
  
  <link name="right_back_wheel">
    <visual>
      <origin rpy="1.57075 0 0" xyz="0 0 0"/>
      <geometry>
        <cylinder length="0.05" radius="0.05"/>
      </geometry>
      <material name="black"/>
    </visual>
  </link>

  <joint name="right_front_wheel_joint" type="continuous">
    <axis rpy="0 0 0" xyz="0 1 0"/>
    <parent link="base_link"/>
    <child link="right_front_wheel"/>
    <origin rpy="0 0 0" xyz="0.12 -0.09 -0.03"/>
  </joint>

  <joint name="right_mid_wheel_joint" type="continuous">
    <axis rpy="0 0 0" xyz="0 1 0"/>
    <parent link="base_link"/>
    <child link="right_mid_wheel"/>
    <origin rpy="0 0 0" xyz="0.0 -0.09 -0.03"/>
  </joint>
  
  <joint name="right_back_wheel_joint" type="continuous">
    <axis rpy="0 0 0" xyz="0 1 0"/>
    <parent link="base_link"/>
    <child link="right_back_wheel"/>
    <origin rpy="0 0 0" xyz="-0.12 -0.09 -0.03"/>
  </joint>
  
  <joint name="joint5_to_joint4" type="revolute">
    <axis xyz=" 0 0 1"/>
    <limit effort = "1000.0" lower = "-3.14" upper = "3.14159" velocity = "0"/>
    <parent link="joint4"/>
    <child link="joint5"/>
    <origin xyz= "-0.096 0 0.06462" rpy = "0 0 -1.5708"/>  
  </joint>

  
  <joint name="joint6_to_joint5" type="revolute">
    <axis xyz="0 0 1"/>
    <limit effort = "1000.0" lower = "-3.14" upper = "3.14159" velocity = "0"/>
    <parent link="joint5"/>
    <child link="joint6"/>
    <origin xyz= "0 -0.07318 0" rpy = "1.5708 -1.5708 0"/>  
  </joint>

  
  <joint name="joint6output_to_joint6" type="revolute">
    <axis xyz="0 0 1"/>
    <limit effort = "1000.0" lower = "-3.14" upper = "3.14159" velocity = "0"/>
    <parent link="joint6"/>
    <child link="joint6_flange"/>
    <origin xyz= "0 0.0456 0" rpy = "-1.5708 0 0"/>  
  </joint>

  
  <joint name="base_joint" type="fixed">
    <parent link="base_footprint"/>
    <child link="base_link"/>
    <origin xyz="0.0 0.0 0.08" rpy="0 0 0"/>
  </joint>

  
  <joint name="base_link_to_arm" type="fixed">
    <parent link="base_link"/>
    <child link="joint1"/>
    <origin xyz="-0.03 0.0 0.087" rpy="0 0 0"/>
  </joint>
  
</robot>
